Workbook

Sheet 作業部屋見取り図
A5: https://www.photo-pick.com/online/5L4HGxBe.link
A6: https://photos.app.goo.gl/kPWz8Cu53vV18if58 | Q6: サイド | U6: 水屋
Q7: テーブル | Y7: 押入れ | AA7: 北 | AB7: 上
Y8: 三段 | AB8: 中
L9: 入り口 | O9: 開閉あり | U9: 襖 | V9: 閉め切り | AB9: 下
G10: 5段
H11: ラック | AB11: 襖
H12: A | R12: 机
W15: 電工 | AA15: エアコン
R16: 椅子 | W16: 作業台
AC18: 窓
G19: ピアノ | V19: 作業用
K20: ベンチ | V20: ラック
K21: プレス用
AC22: 窓
Z26: ぶらさがり
O28: 上
O29: 中
J30: ラック | M30: B | O30: 下
Y32: 上
V33: 押入れ | X33: 南 | Y33: 中
V34: 三段 | Y34: 下

Sheet ラフ配置
A3: 送り先：ぷれこ
A4: 発信者：ChatGPT
A6: 内容：
A8: 【エリア特性シート Ver.1】
A10: ■ 北押入れ 上段
A12: ・取り出しやすさ： | B12: E
A13: ・脚立必要： | B13: 必要
A14: ・重い物向き： | B14: だめだめ
A15: ・軽い物向き： | B15: 出来るだけ
A16: ・長期保管向き： | B16: 基本保管のみ
A17: ・頻繁利用向き： | B17: 不可
A18: ・奥行き：幅：高さ(cm) | B18: 85 | C18: 80 | D18: 50
A19: ・備考： | B19: 空の収納ケース 2*2アーム 車の部品 実質使用率30%（空き空間は多い）
B20: 台になるものはおいていません。一つの空間として利用しています。
A23: ■ 北押入れ 中段
A25: ・取り出しやすさ： | B25: C
A26: ・脚立必要： | B26: 不要
A27: ・重い物向き： | B27: 置き方次第
A28: ・軽い物向き： | B28: ok
A29: ・長期保管向き： | B29: 保管利用はもったいない
A30: ・頻繁利用向き： | B30: 行きにくいけど利用可
A31: ・奥行き：幅：高さ(cm) | B31: 85 | C31: 80 | D31: 80
A32: ・備考： | B32: 現状、かなり詰まってます。利用率80-90％ 工夫するともっと入る。
B33: この空間の中で上段と下段に分かれるように机を置いています。
A36: ■ 北押入れ 下段
A38: ・取り出しやすさ： | B38: D
A39: ・脚立必要： | B39: 不要
A40: ・重い物向き： | B40: ok
A41: ・軽い物向き：
A42: ・長期保管向き： | B42: 中期、長期
A43: ・頻繁利用向き：
A44: ・奥行き：幅：高さ(cm) | B44: 85 | C44: 80 | D44: 70
A45: ・備考： | B45: 奥は特に使いづらい。ケースでおいて利用時はケースを取り出す感じがベスト
B46: 現状40-50％利用中。ほぼケースでおいています。
B47: この空間の中で上段と下段に分かれるように机を置いています。
A49: ■ 南押入れ | B49: 上、中、下での区分けが必要です。作り直してください。
A51: ・取り出しやすさ：
A52: ・脚立必要：
A53: ・重い物向き：
A54: ・軽い物向き：
...

Sheet ラフ配置南
A3: 送り先：ChatGPT
A4: 発信者：ぷれこ
A6: 内容：
A8: 【エリア特性シート Ver.1.2 追加入力用ログ】
A10: ※目的
A11: ・大型ラックの詳細分解
A12: ・収納力とアクセス性の精密化
A13: ・再配置判断材料の強化
A17: ■ 大型ラック（南） 左
A19: ・このエリアの役割（1つ選ぶ or 複数OK）
A20: - よく使う物置き | B20: 短期、中期、空きがあれば長期倉庫扱い
A21: - 一時保管 | B21: 〇
A22: - 長期保管 | B22: 〇
A23: - 機材ストック | B23: ◎
A24: - 仕事・作業関連 | B24: 〇
A25: - その他（ ） | B25: 趣味
A27: ・取り出しやすさ（S～E）： | C27: A-B
A28: ・使用頻度（高・中・低）： | C28: 高－中
A29: ・重さ傾向（軽・中・重）： | C29: ノートバソコンがメイン、台数入れるとかなり重い
A30: ・動かす頻度（よく動く・たまに・固定）： | D30: たまに、ただ動く時は集中するときが多い
A32: ・ここにある代表物（3つくらいでOK）：
A33: ①タンスの中 | B33: ノートパソコン
A34: ② | B34: HDD | C34: PCパーツ | D34: インク
A35: ③ | B35: 書類
A37: ・ここに置いている理由（分かる範囲でOK）： | E37: ノートパソコンを置くために設置
A38: 例：とりあえず置いてる／作業動線上／他に場所がない／固定機器
A40: ・改善候補（思いつけば）：
A41: 例：ここじゃなくてもいい物／移動したい物 | E41: インクが多い、ただ自分で使う為のインクというよりは廃棄がもったいないから
A45: ■ 大型ラック（南） 中央
A47: ・このエリアの役割（1つ選ぶ or 複数OK）
A48: - よく使う物置き | B48: 〇
A49: - 一時保管 | B49: 〇
A50: - 長期保管 | B50: 〇
A51: - 機材ストック | B51: 〇
A52: - 仕事・作業関連 | B52: 〇
A53: - その他（ ） | B53: 〇
A55: ・取り出しやすさ（S～E）： | C55: A
A56: ・使用頻度（高・中・低）： | C56: 高－中
A57: ・重さ傾向（軽・中・重）： | C57: 中まで
A58: ・動かす頻度（よく動く・たまに・固定）： | D58: たまに
...

Sheet アイテムデータ

Sheet S項目
A1: S-ID | B1: S名称 | C1: type | D1: T-ID | E1: T名称 | F1: usage | G1: access | H1: 備考
A2: S-001 | B2: 玄関棚 | C2: S | H2: 初期ルートノード
A3: S-002 | B3: 電工ラック | C3: S | H3: 初期ルートノード
A4: S-003 | B4: 南ラック | C4: S | H4: 初期ルートノード
A5: S-004 | B5: サイドテーブル | C5: S | H5: 初期ルートノード
A6: S-005 | B6: 北押入れ | C6: S | H6: 初期ルートノード
A7: S-006 | B7: 南押入れ | C7: S | H7: 初期ルートノード
A8: S-007 | B8: 机 | C8: S | G8: 初期ルートノード
A9: S-008 | B9: 作業用ラック | C9: S | G9: 初期ルートノード

Sheet T項目
A1: S-ID | B1: S名称 | C1: type | D1: T-ID | E1: T名称 | F1: priority | G1: location | H1: 備考
A2: S-001 | B2: 玄関棚 | C2: 棚 | D2: T-0101 | E2: 天板 | H2: 玄関棚の天板
A3: S-001 | B3: 玄関棚 | C3: 棚 | D3: T-0102 | E3: 上段一段目 | H3: 玄関棚の上段一段目
A4: S-001 | B4: 玄関棚 | C4: 棚 | D4: T-0103 | E4: 上段二段目 | H4: 玄関棚の上段二段目
A5: S-001 | B5: 玄関棚 | C5: 棚 | D5: T-0104 | E5: 上段三段目 | H5: 玄関棚の上段三段目
A6: S-001 | B6: 玄関棚 | C6: 棚 | D6: T-0105 | E6: 上段四段目 | H6: 玄関棚の上段四段目
A7: S-001 | B7: 玄関棚 | C7: 棚 | D7: T-0106 | E7: 引出し | H7: 玄関棚の引出し
A8: S-001 | B8: 玄関棚 | C8: 棚 | D8: T-0107 | E8: 下段一段目 | H8: 玄関棚の下段一段目
A9: S-001 | B9: 玄関棚 | C9: 棚 | D9: T-0108 | E9: 下段二段目 | H9: 玄関棚の下段二段目
A10: S-001 | B10: 玄関棚 | C10: 棚 | D10: T-0109 | E10: 下段三段目 | H10: 玄関棚の下段三段目
A12: S-002 | B12: 電工ラック | C12: T | D12: T-0201 | E12: 天板
A13: S-002 | B13: 電工ラック | C13: T | D13: T-0202 | E13: 天板（中）
A14: S-002 | B14: 電工ラック | C14: T | D14: T-0203 | E14: 一段目
A15: S-002 | B15: 電工ラック | C15: T | D15: T-0204 | E15: 二段目
A16: S-002 | B16: 電工ラック | C16: T | D16: T-0205 | E16: 三段目
A19: S-003 | B19: 南ラック | C19: T | D19: T-0301 | E19: 左棚 | H19: 左側木製デスク上ラック（5段構成）
A20: S-003 | B20: 南ラック | C20: T | D20: T-0302 | E20: 中央棚 | H20: 中央木製ブラウンデスク（天板面）
A21: S-003 | B21: 南ラック | C21: T | D21: T-0303 | E21: 中央スチール棚 | H21: 中央スチールラック（4段・3コンパートメント構成）
A22: S-003 | B22: 南ラック | C22: T | D22: T-0304 | E22: 左底面 | H22: 左棚（T-0301）の足元スペース、撮影済み
A23: S-003 | B23: 南ラック | C23: T | D23: T-0305 | E23: 中央底面 | H23: 中央棚（T-0302）の足元スペース、撮影済み
A24: S-003 | B24: 南ラック | C24: T | D24: T-0306 | E24: 右ガラス扉キャビネット | H24: 右側ガラス扉付ホワイトキャビネット（4段）、本来ノートPC収納用
A25: S-003 | B25: 南ラック | C25: T | D25: T-0307 | E25: 右底面 | H25: 右ガラス扉キャビネット（T-0306）の足元スペース、撮影済み
A26: S-003 | B26: 南ラック | C26: T | D26: T-0308 | E26: 右キャビネット上 | H26: 右ガラス扉キャビネット（T-0306）の上部スペース、撮影済み
A27: S-003 | B27: 南ラック | C27: T | D27: T-0309 | E27: 中央棚上部空域 | H27: 中央棚（T-0302）の上部スペース
A40: S-004 | B40: サイドテーブル | C40: テーブル | D40: T-0401 | E40: 天板 | H40: サイドテーブルの天板
A41: S-004 | B41: サイドテーブル | C41: テーブル | D41: T-0402 | E41: 一段目引出し | H41: サイドテーブルの一段目引出し
A42: S-004 | B42: サイドテーブル | C42: テーブル | D42: T-0403 | E42: 二段目引出し | H42: サイドテーブルの二段目引出し
... A72: S-007 | B72: 机 | C72: T | D72: T-0703 | E72: 下段 | H72: 机本体下、未整理物あり
A76: S-008 | B76: 作業用ラック | C76: T | D76: T-0801 | E76: 上段
A77: S-008 | B77: 作業用ラック | C77: T | D77: T-0802 | E77: 下段

Sheet C項目
A1: parent_id | B1: parent_name | C1: type | D1: C-ID | E1: C名称 | F1: priority | G1: location | H1: 備考
A2: T-0102 | B2: 上段一段目 | C2: ケース | D2: C-010201 | E2: 小物トレー・カゴ | F2: B | G2: 上段一段目 | H2: ピンクトレー・白カゴ
A3: T-0103 | B3: 上段二段目 | C3: ケース | D3: C-010301 | E3: 接着剤ケース | F3: B | G3: 上段二段目 | H3: 接着剤まとめ
A4: T-0103 | B4: 上段二段目 | C4: ケース | D4: C-010302 | E4: 緑カゴ・小物セット | F4: B | G4: 上段二段目 | H4: 緑カゴ含む
A5: T-0104 | B5: 上段三段目 | C5: ケース | D5: C-010401 | E5: 水色引き出し①左列 | F5: B | G5: 上段三段目 | H5: 左列2段
A6: T-0104 | B6: 上段三段目 | C6: ケース | D6: C-010402 | E6: 水色引き出し②中央列 | F6: B | G6: 上段三段目 | H6: 中央列2段
A7: T-0104 | B7: 上段三段目 | C7: ケース | D7: C-010403 | E7: 水色引き出し③右列 | F7: B | G7: 上段三段目 | H7: 右列2段
A8: T-0105 | B8: 四段目・左列上 | C8: ケース | D8: C-010501 | E8: 車・モニタ箱 | F8: C | G8: 四段目・左列上 | H8: 黒ダンボール箱
A9: T-0105 | B9: 四段目・左列下 | C9: ケース | D9: C-010502 | E9: 工具コンテナ | F9: C | G9: 四段目・左列下 | H9: 黒プラスチック
A10: T-0105 | B10: 四段目・中央列 | C10: ケース | D10: C-010503 | E10: 黒ネジ・部品ボックス | F10: C | G10: 四段目・中央列 | H10: グレーインナーボックス（ネジDB）
A11: T-0105 | B11: 四段目・右列 | C11: ケース | D11: C-010504 | E11: 白ネジボックス | F11: C | G11: 四段目・右列 | H11: グレーインナーボックス（ネジDB）
A12: T-0108 | B12: 下段二段目 | C12: ケース | D12: C-010801 | E12: REGAL赤箱 | F12: B | G12: 下段二段目 | H12: 箱
... A21: T-0402 | B21: 引き出し1段目 | C21: ケース | D21: C-040201 | E21: 工具ケース | F21: C | G21: 引き出し1段目 | H21: 工具・刃物収納
A22: T-0403 | B22: 引き出し2段目 | C22: ケース | D22: C-040301 | E22: 白メッシュカゴ | F22: B | G22: 引き出し2段目
A23: T-0802 | B23: 下段 | C23: ケース | D23: C-080201 | E23: 緑のバケツ | F23: B | H23: ゴミ箱として使用
A28: T-0304 | B28: 左底面 | C28: ケース | D28: C-030401 | E28: 工具キャリーバッグ（赤黒） | F28: B
A29: T-0304 | B29: 左底面 | C29: ケース | D29: C-030402 | E29: パーツケース（青蓋） | F29: B
A30: T-0305 | B30: 中央底面 | C30: ケース | D30: C-030501 | E30: シルバーアルミミニケース | F30: B
A31: T-0305 | B31: 中央底面 | C31: ケース | D31: C-030502 | E31: 白プラスチックコンテナ（深型）1 | F31: B | H31: 2個あるうちの1つ
A32: T-0305 | B32: 中央底面 | C32: ケース | D32: C-030503 | E32: 白プラスチックコンテナ（深型）2 | F32: B | H32: 2個あるうちの2つ目
A33: T-0305 | B33: 中央底面 | C33: ケース | D33: C-030504 | E33: 白いダストボックス（STORAGE BOX） | F33: B
A34: T-0307 | B34: 右底面 | C34: ケース | D34: C-030701 | E34: Canon プリンター PIXUS TS8630 箱 | F34: B
A35: T-0307 | B35: 右底面 | C35: ケース | D35: C-030702 | E35: 黒ワイヤーバスケット（キャスター付） | F35: B
A36: T-0308 | B36: 右キャビネット上 | C36: ケース | D36: C-030801 | E36: ELD-HTV020UBK 外付けHDD箱 | F36: B
A37: T-0308 | B37: 右キャビネット上 | C37: ケース | D37: C-030802 | E37: ベージュトートバッグ | F37: B
A38: T-0309 | B38: 中央棚上部空域 | C38: ケース | D38: C-030901 | E38: EPSON インク EP-716A 箱 | F38: B
A39: T-0309 | B39: 中央棚上部空域 | C39: ケース | D39: C-030902 | E39: BeBox 黒プラスチックコンテナ | F39: B
A40: T-0301 | B40: 左棚 | C40: ケース | D40: C-030101 | E40: ガラス瓶・試験管立て | F40: B | G40: 1段目
A41: T-0301 | B41: 左棚 | C41: ケース | D41: C-030102 | E41: SNOOPYボックス・書類箱 | F41: B | G41: 2段目
A42: T-0301 | B42: 左棚 | C42: ケース | D42: C-030103 | E42: スリム引き出しケース・アーム固定 | F42: B | G42: 3段目
A43: T-0301 | B43: 左棚 | C43: ケース | D43: C-030104 | E43: クリアファイル・小物ケース | F43: B | G43: 4段目
A44: T-0301 | B44: 左棚 | C44: ケース | D44: C-030105 | E44: マグネットツールパネル | F44: B | G44: 5段目
A45: T-0302 | B45: 中央棚 | C45: ケース | D45: C-030201 | E45: クリアファイルホルダー | F45: B | G45: 天板左側
A46: T-0302 | B46: 中央棚 | C46: ケース | D46: C-030202 | E46: 不織布収納ケース | F46: B | G46: 天板中央
A47: T-0302 | B47: 中央棚 | C47: ケース | D47: C-030203 | E47: テープ類・ピンク付箋ケース | F47: B | G47: 天板右側
A48: T-0303 | B48: 中央スチール棚 | C48: ケース | D48: C-030301 | E48: 白プラスチックバスケット浅型大 | F48: B | G48: 1段目左
A49: T-0303 | B49: 中央スチール棚 | C49: ケース | D49: C-030302 | E49: 白プラスチックバスケット浅型大 | F49: B | G49: 1段目中央
A50: T-0303 | B50: 中央スチール棚 | C50: ケース | D50: C-030303 | E50: 白プラスチックバスケット浅型大 | F50: B | G50: 1段目右
A51: T-0303 | B51: 中央スチール棚 | C51: ケース | D51: C-030304 | E51: SNOOPYミニトート・工具ケース | F51: B | G51: 2段目左
... A62: T-0306 | B62: 右ガラス扉キャビネット | C62: ケース | D62: C-030606 | E62: 緑プラスチックバスケット深型 | F62: B | G62: 4段目全体

Sheet アイテム入力
A1: アイテム入力 | N1: 登録用コピー（値貼り付け）
A2: 黄色の欄を入力。登録用コピー列を値として、アイテム項目の次の空行へ貼り付けます。
A4: Items-ID候補 | B4: C-ID（選択） | C4: 親T-ID | D4: 親T名称 | E4: C名称 | F4: Items名称 | G4: type | H4: usage | I4: access | J4: 備考 | K4: 状態 | L4: 登録日時 | N4: parent_id | O4: parent_type | P4: parent_name | Q4: type | R4: Items-ID | S4: Items名称 | T4: usage | U4: access | V4: 備考 | W4: 補足1 | X4: 補足2 | Y4: 状態 | Z4: 登録日時 | AA4: ID_Num
A5: =IF($F5="","","I-"&TEXT(MAX(アイテム項目!$N$2:$N$1000)+COUNTIF($F$5:F5,"<>"),"00000")) | C5: =IFERROR(INDEX(C項目!$A$2:$A$62,MATCH($B5,C項目!$D$2:$D$62,0)),"") | D5: =IFERROR(INDEX(C項目!$B$2:$B$62,MATCH($B5,C項目!$D$2:$D$62,0)),"") | E5: =IFERROR(INDEX(C項目!$E$2:$E$62,MATCH($B5,C項目!$D$2:$D$62,0)),"") | K5: =IF($F5="","","有効") | L5: =IF($F5="","",NOW()) | N5: =IF($F5="","",$B5) | O5: =IF($F5="","","C") | P5: =IF($F5="","",$E5) | Q5: =IF($F5="","",$G5) | R5: =IF($F5="","",$A5) | S5: =IF($F5="","",$F5) | T5: =IF($F5="","",$H5) | U5: =IF($F5="","",$I5) | V5: =IF($F5="","",$J5) | Y5: =IF($F5="","",$K5) | Z5: =IF($F5="","",$L5) | AA5: =IF($R5="","",VALUE(MID($R5,3,5)))
A6: =IF($F6="","","I-"&TEXT(MAX(アイテム項目!$N$2:$N$1000)+COUNTIF($F$5:F6,"<>"),"00000")) | C6: =IFERROR(INDEX(C項目!$A$2:$A$62,MATCH($B6,C項目!$D$2:$D$62,0)),"") | D6: =IFERROR(INDEX(C項目!$B$2:$B$62,MATCH($B6,C項目!$D$2:$D$62,0)),"") | E6: =IFERROR(INDEX(C項目!$E$2:$E$62,MATCH($B6,C項目!$D$2:$D$62,0)),"") | K6: =IF($F6="","","有効") | L6: =IF($F6="","",NOW()) | N6: =IF($F6="","",$B6) | O6: =IF($F6="","","C") | P6: =IF($F6="","",$E6) | Q6: =IF($F6="","",$G6) | R6: =IF($F6="","",$A6) | S6: =IF($F6="","",$F6) | T6: =IF($F6="","",$H6) | U6: =IF($F6="","",$I6) | V6: =IF($F6="","",$J6) | Y6: =IF($F6="","",$K6) | Z6: =IF($F6="","",$L6) | AA6: =IF($R6="","",VALUE(MID($R6,3,5)))
A7: =IF($F7="","","I-"&TEXT(MAX(アイテム項目!$N$2:$N$1000)+COUNTIF($F$5:F7,"<>"),"00000")) | C7: =IFERROR(INDEX(C項目!$A$2:$A$62,MATCH($B7,C項目!$D$2:$D$62,0)),"") | D7: =IFERROR(INDEX(C項目!$B$2:$B$62,MATCH($B7,C項目!$D$2:$D$62,0)),"") | E7: =IFERROR(INDEX(C項目!$E$2:$E$62,MATCH($B7,C項目!$D$2:$D$62,0)),"") | K7: =IF($F7="","","有効") | L7: =IF($F7="","",NOW()) | N7: =IF($F7="","",$B7) | O7: =IF($F7="","","C") | P7: =IF($F7="","",$E7) | Q7: =IF($F7="","",$G7) | R7: =IF($F7="","",$A7) | S7: =IF($F7="","",$F7) | T7: =IF($F7="","",$H7) | U7: =IF($F7="","",$I7) | V7: =IF($F7="","",$J7) | Y7: =IF($F7="","",$K7) | Z7: =IF($F7="","",$L7) | AA7: =IF($R7="","",VALUE(MID($R7,3,5)))
A8: =IF($F8="","","I-"&TEXT(MAX(アイテム項目!$N$2:$N$1000)+COUNTIF($F$5:F8,"<>"),"00000")) | C8: =IFERROR(INDEX(C項目!$A$2:$A$62,MATCH($B8,C項目!$D$2:$D$62,0)),"") | D8: =IFERROR(INDEX(C項目!$B$2:$B$62,MATCH($B8,C項目!$D$2:$D$62,0)),"") | E8: =IFERROR(INDEX(C項目!$E$2:$E$62,MATCH($B8,C項目!$D$2:$D$62,0)),"") | K8: =IF($F8="","","有効") | L8: =IF($F8="","",NOW()) | N8: =IF($F8="","",$B8) | O8: =IF($F8="","","C") | P8: =IF($F8="","",$E8) | Q8: =IF($F8="","",$G8) | R8: =IF($F8="","",$A8) | S8: =IF($F8="","",$F8) | T8: =IF($F8="","",$H8) | U8: =IF($F8="","",$I8) | V8: =IF($F8="","",$J8) | Y8: =IF($F8="","",$K8) | Z8: =IF($F8="","",$L8) | AA8: =IF($R8="","",VALUE(MID($R8,3,5)))
A9: =IF($F9="","","I-"&TEXT(MAX(アイテム項目!$N$2:$N$1000)+COUNTIF($F$5:F9,"<>"),"00000")) | C9: =IFERROR(INDEX(C項目!$A$2:$A$62,MATCH($B9,C項目!$D$2:$D$62,0)),"") | D9: =IFERROR(INDEX(C項目!$B$2:$B$62,MATCH($B9,C項目!$D$2:$D$62,0)),"") | E9: =IFERROR(INDEX(C項目!$E$2:$E$62,MATCH($B9,C項目!$D$2:$D$62,0)),"") | K9: =IF($F9="","","有効") | L9: =IF($F9="","",NOW()) | N9: =IF($F9="","",$B9) | O9: =IF($F9="","","C") | P9: =IF($F9="","",$E9) | Q9: =IF($F9="","",$G9) | R9: =IF($F9="","",$A9) | S9: =IF($F9="","",$F9) | T9: =IF($F9="","",$H9) | U9: =IF($F9="","",$I9) | V9: =IF($F9="","",$J9) | Y9: =IF($F9="","",$K9) | Z9: =IF($F9="","",$L9) | AA9: =IF($R9="","",VALUE(MID($R9,3,5)))
A10: =IF($F10="","","I-"&TEXT(MAX(アイテム項目!$N$2:$N$1000)+COUNTIF($F$5:F10,"<>"),"00000")) | C10: =IFERROR(INDEX(C項目!$A$2:$A$62,MATCH($B10,C項目!$D$2:$D$62,0)),"") | D10: =IFERROR(INDEX(C項目!$B$2:$B$62,MATCH($B10,C項目!$D$2:$D$62,0)),"") | E10: =IFERROR(INDEX(C項目!$E$2:$E$62,MATCH($B10,C項目!$D$2:$D$62,0)),"") | K10: =IF($F10="","","有効") | L10: =IF($F10="","",NOW()) | N10: =IF($F10="","",$B10) | O10: =IF($F10="","","C") | P10: =IF($F10="","",$E10) | Q10: =IF($F10="","",$G10) | R10: =IF($F10="","",$A10) | S10: =IF($F10="","",$F10) | T10: =IF($F10="","",$H10) | U10: =IF($F10="","",$I10) | V10: =IF($F10="","",$J10) | Y10: =IF($F10="","",$K10) | Z10: =IF($F10="","",$L10) | AA10: =IF($R10="","",VALUE(MID($R10,3,5)))
A11: =IF($F11="","","I-"&TEXT(MAX(アイテム項目!$N$2:$N$1000)+COUNTIF($F$5:F11,"<>"),"00000")) | C11: =IFERROR(INDEX(C項目!$A$2:$A$62,MATCH($B11,C項目!$D$2:$D$62,0)),"") | D11: =IFERROR(INDEX(C項目!$B$2:$B$62,MATCH($B11,C項目!$D$2:$D$62,0)),"") | E11: =IFERROR(INDEX(C項目!$E$2:$E$62,MATCH($B11,C項目!$D$2:$D$62,0)),"") | K11: =IF($F11="","","有効") | L11: =IF($F11="","",NOW()) | N11: =IF($F11="","",$B11) | O11: =IF($F11="","","C") | P11: =IF($F11="","",$E11) | Q11: =IF($F11="","",$G11) | R11: =IF($F11="","",$A11) | S11: =IF($F11="","",$F11) | T11: =IF($F11="","",$H11) | U11: =IF($F11="","",$I11) | V11: =IF($F11="","",$J11) | Y11: =IF($F11="","",$K11) | Z11: =IF($F11="","",$L11) | AA11: =IF($R11="","",VALUE(MID($R11,3,5)))
A12: =IF($F12="","","I-"&TEXT(MAX(アイテム項目!$N$2:$N$1000)+COUNTIF($F$5:F12,"<>"),"00000")) | C12: =IFERROR(INDEX(C項目!$A$2:$A$62,MATCH($B12,C項目!$D$2:$D$62,0)),"") | D12: =IFERROR(INDEX(C項目!$B$2:$B$62,MATCH($B12,C項目!$D$2:$D$62,0)),"") | E12: =IFERROR(INDEX(C項目!$E$2:$E$62,MATCH($B12,C項目!$D$2:$D$62,0)),"") | K12: =IF($F12="","","有効") | L12: =IF($F12="","",NOW()) | N12: =IF($F12="","",$B12) | O12: =IF($F12="","","C") | P12: =IF($F12="","",$E12) | Q12: =IF($F12="","",$G12) | R12: =IF($F12="","",$A12) | S12: =IF($F12="","",$F12) | T12: =IF($F12="","",$H12) | U12: =IF($F12="","",$I12) | V12: =IF($F12="","",$J12) | Y12: =IF($F12="","",$K12) | Z12: =IF($F12="","",$L12) | AA12: =IF($R12="","",VALUE(MID($R12,3,5)))
A13: =IF($F13="","","I-"&TEXT(MAX(アイテム項目!$N$2:$N$1000)+COUNTIF($F$5:F13,"<>"),"00000")) | C13: =IFERROR(INDEX(C項目!$A$2:$A$62,MATCH($B13,C項目!$D$2:$D$62,0)),"") | D13: =IFERROR(INDEX(C項目!$B$2:$B$62,MATCH($B13,C項目!$D$2:$D$62,0)),"") | E13: =IFERROR(INDEX(C項目!$E$2:$E$62,MATCH($B13,C項目!$D$2:$D$62,0)),"") | K13: =IF($F13="","","有効") | L13: =IF($F13="","",NOW()) | N13: =IF($F13="","",$B13) | O13: =IF($F13="","","C") | P13: =IF($F13="","",$E13) | Q13: =IF($F13="","",$G13) | R13: =IF($F13="","",$A13) | S13: =IF($F13="","",$F13) | T13: =IF($F13="","",$H13) | U13: =IF($F13="","",$I13) | V13: =IF($F13="","",$J13) | Y13: =IF($F13="","",$K13) | Z13: =IF($F13="","",$L13) | AA13: =IF($R13="","",VALUE(MID($R13,3,5)))
A14: =IF($F14="","","I-"&TEXT(MAX(アイテム項目!$N$2:$N$1000)+COUNTIF($F$5:F14,"<>"),"00000")) | C14: =IFERROR(INDEX(C項目!$A$2:$A$62,MATCH($B14,C項目!$D$2:$D$62,0)),"") | D14: =IFERROR(INDEX(C項目!$B$2:$B$62,MATCH($B14,C項目!$D$2:$D$62,0)),"") | E14: =IFERROR(INDEX(C項目!$E$2:$E$62,MATCH($B14,C項目!$D$2:$D$62,0)),"") | K14: =IF($F14="","","有効") | L14: =IF($F14="","",NOW()) | N14: =IF($F14="","",$B14) | O14: =IF($F14="","","C") | P14: =IF($F14="","",$E14) | Q14: =IF($F14="","",$G14) | R14: =IF($F14="","",$A14) | S14: =IF($F14="","",$F14) | T14: =IF($F14="","",$H14) | U14: =IF($F14="","",$I14) | V14: =IF($F14="","",$J14) | Y14: =IF($F14="","",$K14) | Z14: =IF($F14="","",$L14) | AA14: =IF($R14="","",VALUE(MID($R14,3,5)))
A15: =IF($F15="","","I-"&TEXT(MAX(アイテム項目!$N$2:$N$1000)+COUNTIF($F$5:F15,"<>"),"00000")) | C15: =IFERROR(INDEX(C項目!$A$2:$A$62,MATCH($B15,C項目!$D$2:$D$62,0)),"") | D15: =IFERROR(INDEX(C項目!$B$2:$B$62,MATCH($B15,C項目!$D$2:$D$62,0)),"") | E15: =IFERROR(INDEX(C項目!$E$2:$E$62,MATCH($B15,C項目!$D$2:$D$62,0)),"") | K15: =IF($F15="","","有効") | L15: =IF($F15="","",NOW()) | N15: =IF($F15="","",$B15) | O15: =IF($F15="","","C") | P15: =IF($F15="","",$E15) | Q15: =IF($F15="","",$G15) | R15: =IF($F15="","",$A15) | S15: =IF($F15="","",$F15) | T15: =IF($F15="","",$H15) | U15: =IF($F15="","",$I15) | V15: =IF($F15="","",$J15) | Y15: =IF($F15="","",$K15) | Z15: =IF($F15="","",$L15) | AA15: =IF($R15="","",VALUE(MID($R15,3,5)))
A16: =IF($F16="","","I-"&TEXT(MAX(アイテム項目!$N$2:$N$1000)+COUNTIF($F$5:F16,"<>"),"00000")) | C16: =IFERROR(INDEX(C項目!$A$2:$A$62,MATCH($B16,C項目!$D$2:$D$62,0)),"") | D16: =IFERROR(INDEX(C項目!$B$2:$B$62,MATCH($B16,C項目!$D$2:$D$62,0)),"") | E16: =IFERROR(INDEX(C項目!$E$2:$E$62,MATCH($B16,C項目!$D$2:$D$62,0)),"") | K16: =IF($F16="","","有効") | L16: =IF($F16="","",NOW()) | N16: =IF($F16="","",$B16) | O16: =IF($F16="","","C") | P16: =IF($F16="","",$E16) | Q16: =IF($F16="","",$G16) | R16: =IF($F16="","",$A16) | S16: =IF($F16="","",$F16) | T16: =IF($F16="","",$H16) | U16: =IF($F16="","",$I16) | V16: =IF($F16="","",$J16) | Y16: =IF($F16="","",$K16) | Z16: =IF($F16="","",$L16) | AA16: =IF($R16="","",VALUE(MID($R16,3,5)))
... A24: =IF($F24="","","I-"&TEXT(MAX(アイテム項目!$N$2:$N$1000)+COUNTIF($F$5:F24,"<>"),"00000")) | C24: =IFERROR(INDEX(C項目!$A$2:$A$62,MATCH($B24,C項目!$D$2:$D$62,0)),"") | D24: =IFERROR(INDEX(C項目!$B$2:$B$62,MATCH($B24,C項目!$D$2:$D$62,0)),"") | E24: =IFERROR(INDEX(C項目!$E$2:$E$62,MATCH($B24,C項目!$D$2:$D$62,0)),"") | K24: =IF($F24="","","有効") | L24: =IF($F24="","",NOW()) | N24: =IF($F24="","",$B24) | O24: =IF($F24="","","C") | P24: =IF($F24="","",$E24) | Q24: =IF($F24="","",$G24) | R24: =IF($F24="","",$A24) | S24: =IF($F24="","",$F24) | T24: =IF($F24="","",$H24) | U24: =IF($F24="","",$I24) | V24: =IF($F24="","",$J24) | Y24: =IF($F24="","",$K24) | Z24: =IF($F24="","",$L24) | AA24: =IF($R24="","",VALUE(MID($R24,3,5)))

Sheet アイテム項目
A1: parent_id | B1: parent_type | C1: parent_name | D1: type | E1: Items-ID | F1: Items名称 | G1: usage | H1: access | I1: 備考 | L1: 状態 | M1: 登録日時 | N1: ID_Num（補助）
A2: C-010301 | B2: C | C2: 接着剤ケース | D2: 接着剤 | E2: I-00001 | F2: 瞬間接着剤 | G2: 接着 | H2: B | I2: 白黒・白赤小パッケージ計3点、ミニチューブ3本入り含む | N2: =IFERROR(VALUE(MID(E2,3,5)),"") -> 1
A3: C-010301 | B3: C | C3: 接着剤ケース | D3: 接着剤 | E3: I-00002 | F3: エポキシ2液混合接着剤 | G3: 接着 | H3: B | I3: 赤オレンジ・オレンジ黒赤台紙パッケージ計4点 | N3: =IFERROR(VALUE(MID(E3,3,5)),"") -> 2
A4: C-010301 | B4: C | C4: 接着剤ケース | D4: 接着剤 | E4: I-00003 | F4: 強力接着剤チューブ | G4: 接着 | H4: B | I4: カゴ内、2本セット×2種類 | N4: =IFERROR(VALUE(MID(E4,3,5)),"") -> 3
A5: C-010301 | B5: C | C5: 接着剤ケース | D5: 接着剤 | E5: I-00004 | F5: 多用途ボンド | G5: 接着 | H5: B | I5: カゴ内、大きめチューブ | N5: =IFERROR(VALUE(MID(E5,3,5)),"") -> 4
A6: C-010301 | B6: C | C6: 接着剤ケース | D6: 接着剤 | E6: I-00005 | F6: うるし | G6: 塗装 | H6: B | I6: カゴ内、オレンジパッケージ | N6: =IFERROR(VALUE(MID(E6,3,5)),"") -> 5
A7: C-010201 | B7: C | C7: 小物トレー・カゴ | D7: 文房具 | E7: I-00006 | F7: ペン類 | G7: 文房具 | H7: B | I7: ボールペン・シャープ・蛍光ペン等複数本 | N7: =IFERROR(VALUE(MID(E7,3,5)),"") -> 6
A8: C-010201 | B8: C | C8: 小物トレー・カゴ | D8: 文房具 | E8: I-00007 | F8: 消しゴム | G8: 文房具 | H8: B | I8: MONOゼロノック式 | N8: =IFERROR(VALUE(MID(E8,3,5)),"") -> 7
A9: C-010201 | B9: C | C9: 小物トレー・カゴ | D9: 工具 | E9: I-00008 | F9: ハサミ・カッター | G9: 工具 | H9: B | I9: カッターナイフ含む | N9: =IFERROR(VALUE(MID(E9,3,5)),"") -> 8
A10: C-010201 | B10: C | C10: 小物トレー・カゴ | D10: 小物 | E10: I-00009 | F10: つめ切り・爪やすり | G10: 日用品 | H10: B | I10: 台紙付きつめ切り・金属製やすり | N10: =IFERROR(VALUE(MID(E10,3,5)),"") -> 9
A11: C-010201 | B11: C | C11: 小物トレー・カゴ | D11: 小物 | E11: I-00010 | F11: クリップ類 | G11: 文房具 | H11: B | I11: 各種クリップ | N11: =IFERROR(VALUE(MID(E11,3,5)),"") -> 10
A12: C-010201 | B12: C | C12: 小物トレー・カゴ | D12: 電材 | E12: I-00011 | F12: 結束バンド（白） | G12: 電材 | H12: B | I12: 10cm・120本入パッケージ | N12: =IFERROR(VALUE(MID(E12,3,5)),"") -> 11
A13: C-010201 | B13: C | C13: 小物トレー・カゴ | D13: 小物 | E13: I-00012 | F13: 小ネジボックス | G13: ネジ | H13: B | I13: 小ネジ各種入りボックス | N13: =IFERROR(VALUE(MID(E13,3,5)),"") -> 12
... A67: C-010502 | B67: C | C67: 工具コンテナ | D67: 不明 | E67: I-00066 | F67: 木製ブロック | G67: 不明 | H67: C | I67: 3点 | N67: =IFERROR(VALUE(MID(E67,3,5)),"") -> 66
A68: T-0106 | B68: T | C68: 引出し | D68: 玄関小物 | E68: I-00067 | F68: 茶白ラインロールテープ | G68: テープ | H68: B | N68: =IFERROR(VALUE(MID(E68,3,5)),"") -> 67
A69: T-0106 | B69: T | C69: 引出し | D69: 玄関小物 | E69: I-00068 | F69: 茶色ロールシート | G69: テープ | H69: B | N69: =IFERROR(VALUE(MID(E69,3,5)),"") -> 68
A70: T-0106 | B70: T | C70: 引出し | D70: 玄関小物 | E70: I-00069 | F70: 白ロールテープ | G70: テープ | H70: B | N70: =IFERROR(VALUE(MID(E70,3,5)),"") -> 69
A71: T-0106 | B71: T | C71: 引出し | D71: 玄関小物 | E71: I-00070 | F71: 黒ロールテープ | G71: テープ | H71: B | N71: =IFERROR(VALUE(MID(E71,3,5)),"") -> 70
A72: T-0106 | B72: T | C72: 引出し | D72: 玄関小物 | E72: I-00071 | F72: グルースティック | G72: 接着 | H72: B | N72: =IFERROR(VALUE(MID(E72,3,5)),"") -> 71
A73: T-0106 | B73: T | C73: 引出し | D73: 玄関小物 | E73: I-00072 | F73: カッターナイフ（大型・黄黒） | G73: 工具 | H73: B | N73: =IFERROR(VALUE(MID(E73,3,5)),"") -> 72
A74: T-0106 | B74: T | C74: 引出し | D74: 玄関小物 | E74: I-00073 | F74: カッターナイフ（黄黒） | G74: 工具 | H74: B | N74: =IFERROR(VALUE(MID(E74,3,5)),"") -> 73
A75: T-0106 | B75: T | C75: 引出し | D75: 玄関小物 | E75: I-00074 | F75: ハサミ（赤持ち手） | G75: 工具 | H75: B | N75: =IFERROR(VALUE(MID(E75,3,5)),"") -> 74
A76: T-0106 | B76: T | C76: 引出し | D76: 玄関小物 | E76: I-00075 | F76: ハサミ（黒/グレー持ち手） | G76: 工具 | H76: B | N76: =IFERROR(VALUE(MID(E76,3,5)),"") -> 75
A77: T-0106 | B77: T | C77: 引出し | D77: 玄関小物 | E77: I-00076 | F77: 半透明仕切りケース | G77: 収納 | H77: B | N77: =IFERROR(VALUE(MID(E77,3,5)),"") -> 76
A78: T-0106 | B78: T | C78: 引出し | D78: 玄関小物 | E78: I-00077 | F78: 彫刻刀セット | G78: 工具 | H78: B | N78: =IFERROR(VALUE(MID(E78,3,5)),"") -> 77
A79: T-0106 | B79: T | C79: 引出し | D79: 玄関小物 | E79: I-00078 | F79: 乾電池 | G79: 電材 | H79: B | N79: =IFERROR(VALUE(MID(E79,3,5)),"") -> 78
... A91: C-010901 | B91: C | C91: 水色大型BOX | D91: ケース | E91: I-00090 | F91: 木製柄付き工具 | G91: 工具 | H91: B | N91: =IFERROR(VALUE(MID(E91,3,5)),"") -> 90
N92: =IFERROR(VALUE(MID(E92,3,5)),"")
N93: =IFERROR(VALUE(MID(E93,3,5)),"")
N94: =IFERROR(VALUE(MID(E94,3,5)),"")
N95: =IFERROR(VALUE(MID(E95,3,5)),"")
N96: =IFERROR(VALUE(MID(E96,3,5)),"")
N97: =IFERROR(VALUE(MID(E97,3,5)),"")
N98: =IFERROR(VALUE(MID(E98,3,5)),"")
N99: =IFERROR(VALUE(MID(E99,3,5)),"")
N100: =IFERROR(VALUE(MID(E100,3,5)),"")
N101: =IFERROR(VALUE(MID(E101,3,5)),"")
N102: =IFERROR(VALUE(MID(E102,3,5)),"")
N103: =IFERROR(VALUE(MID(E103,3,5)),"")
... N115: =IFERROR(VALUE(MID(E115,3,5)),"")
...

Sheet ネジDB
A1: parent_id | B1: parent_type | C1: parent_name | D1: N-ID | E1: 色 | F1: 頭形状 | G1: サイズ区分 | H1: access | I1: 備考
A2: C-010503 | B2: C | C2: 黒ネジ・部品ボックス | D2: N-00001 | E2: 黒 | F2: 未分類 | G2: 未分類 | H2: B | I2: 内部未調査
A3: C-010504 | B3: C | C3: 白ネジボックス | D3: N-00002 | E3: 銀 | F3: 未分類 | G3: 未分類 | H3: B | I3: 内部未調査

Sheet アイテムビューア
A1: S-ID | B1: S名称 | C1: T-ID | D1: T名称 | E1: C-ID | F1: C名称 | G1: Items-ID | H1: Items名称 | I1: usage | J1: access | K1: 備考
A2: =IFERROR(INDEX(T項目!$A:$A,MATCH(アイテムビューア!$C2,T項目!$D:$D,0)),"") -> S-001 | B2: =IFERROR(INDEX(S項目!$B:$B,MATCH(アイテムビューア!$A2,S項目!$A:$A,0)),"") -> 玄関棚 | C2: =IFERROR(INDEX(C項目!$A:$A,MATCH(アイテムビューア!$E2,C項目!$D:$D,0)),"") -> T-0103 | D2: =IFERROR(INDEX(T項目!$E:$E,MATCH(アイテムビューア!$C2,T項目!$D:$D,0)),"") -> 上段二段目 | E2: =アイテム項目!$A2 -> C-010301 | F2: =IFERROR(INDEX(C項目!$E:$E,MATCH(アイテムビューア!$E2,C項目!$D:$D,0)),"") -> 接着剤ケース | G2: =アイテム項目!$E2 -> I-00001 | H2: =アイテム項目!$F2 -> 瞬間接着剤 | I2: =アイテム項目!$G2 -> 接着 | J2: =アイテム項目!$H2 -> B | K2: =アイテム項目!$I2 -> 白黒・白赤小パッケージ計3点、ミニチューブ3本入り含む
A3: =IFERROR(INDEX(T項目!$A:$A,MATCH(アイテムビューア!$C3,T項目!$D:$D,0)),"") -> S-001 | B3: =IFERROR(INDEX(S項目!$B:$B,MATCH(アイテムビューア!$A3,S項目!$A:$A,0)),"") -> 玄関棚 | C3: =IFERROR(INDEX(C項目!$A:$A,MATCH(アイテムビューア!$E3,C項目!$D:$D,0)),"") -> T-0103 | D3: =IFERROR(INDEX(T項目!$E:$E,MATCH(アイテムビューア!$C3,T項目!$D:$D,0)),"") -> 上段二段目 | E3: =アイテム項目!$A3 -> C-010301 | F3: =IFERROR(INDEX(C項目!$E:$E,MATCH(アイテムビューア!$E3,C項目!$D:$D,0)),"") -> 接着剤ケース | G3: =アイテム項目!$E3 -> I-00002 | H3: =アイテム項目!$F3 -> エポキシ2液混合接着剤 | I3: =アイテム項目!$G3 -> 接着 | J3: =アイテム項目!$H3 -> B | K3: =アイテム項目!$I3 -> 赤オレンジ・オレンジ黒赤台紙パッケージ計4点
A4: =IFERROR(INDEX(T項目!$A:$A,MATCH(アイテムビューア!$C4,T項目!$D:$D,0)),"") -> S-001 | B4: =IFERROR(INDEX(S項目!$B:$B,MATCH(アイテムビューア!$A4,S項目!$A:$A,0)),"") -> 玄関棚 | C4: =IFERROR(INDEX(C項目!$A:$A,MATCH(アイテムビューア!$E4,C項目!$D:$D,0)),"") -> T-0103 | D4: =IFERROR(INDEX(T項目!$E:$E,MATCH(アイテムビューア!$C4,T項目!$D:$D,0)),"") -> 上段二段目 | E4: =アイテム項目!$A4 -> C-010301 | F4: =IFERROR(INDEX(C項目!$E:$E,MATCH(アイテムビューア!$E4,C項目!$D:$D,0)),"") -> 接着剤ケース | G4: =アイテム項目!$E4 -> I-00003 | H4: =アイテム項目!$F4 -> 強力接着剤チューブ | I4: =アイテム項目!$G4 -> 接着 | J4: =アイテム項目!$H4 -> B | K4: =アイテム項目!$I4 -> カゴ内、2本セット×2種類
A5: =IFERROR(INDEX(T項目!$A:$A,MATCH(アイテムビューア!$C5,T項目!$D:$D,0)),"") -> S-001 | B5: =IFERROR(INDEX(S項目!$B:$B,MATCH(アイテムビューア!$A5,S項目!$A:$A,0)),"") -> 玄関棚 | C5: =IFERROR(INDEX(C項目!$A:$A,MATCH(アイテムビューア!$E5,C項目!$D:$D,0)),"") -> T-0103 | D5: =IFERROR(INDEX(T項目!$E:$E,MATCH(アイテムビューア!$C5,T項目!$D:$D,0)),"") -> 上段二段目 | E5: =アイテム項目!$A5 -> C-010301 | F5: =IFERROR(INDEX(C項目!$E:$E,MATCH(アイテムビューア!$E5,C項目!$D:$D,0)),"") -> 接着剤ケース | G5: =アイテム項目!$E5 -> I-00004 | H5: =アイテム項目!$F5 -> 多用途ボンド | I5: =アイテム項目!$G5 -> 接着 | J5: =アイテム項目!$H5 -> B | K5: =アイテム項目!$I5 -> カゴ内、大きめチューブ
A6: =IFERROR(INDEX(T項目!$A:$A,MATCH(アイテムビューア!$C6,T項目!$D:$D,0)),"") -> S-001 | B6: =IFERROR(INDEX(S項目!$B:$B,MATCH(アイテムビューア!$A6,S項目!$A:$A,0)),"") -> 玄関棚 | C6: =IFERROR(INDEX(C項目!$A:$A,MATCH(アイテムビューア!$E6,C項目!$D:$D,0)),"") -> T-0103 | D6: =IFERROR(INDEX(T項目!$E:$E,MATCH(アイテムビューア!$C6,T項目!$D:$D,0)),"") -> 上段二段目 | E6: =アイテム項目!$A6 -> C-010301 | F6: =IFERROR(INDEX(C項目!$E:$E,MATCH(アイテムビューア!$E6,C項目!$D:$D,0)),"") -> 接着剤ケース | G6: =アイテム項目!$E6 -> I-00005 | H6: =アイテム項目!$F6 -> うるし | I6: =アイテム項目!$G6 -> 塗装 | J6: =アイテム項目!$H6 -> B | K6: =アイテム項目!$I6 -> カゴ内、オレンジパッケージ
A7: =IFERROR(INDEX(T項目!$A:$A,MATCH(アイテムビューア!$C7,T項目!$D:$D,0)),"") -> S-001 | B7: =IFERROR(INDEX(S項目!$B:$B,MATCH(アイテムビューア!$A7,S項目!$A:$A,0)),"") -> 玄関棚 | C7: =IFERROR(INDEX(C項目!$A:$A,MATCH(アイテムビューア!$E7,C項目!$D:$D,0)),"") -> T-0102 | D7: =IFERROR(INDEX(T項目!$E:$E,MATCH(アイテムビューア!$C7,T項目!$D:$D,0)),"") -> 上段一段目 | E7: =アイテム項目!$A7 -> C-010201 | F7: =IFERROR(INDEX(C項目!$E:$E,MATCH(アイテムビューア!$E7,C項目!$D:$D,0)),"") -> 小物トレー・カゴ | G7: =アイテム項目!$E7 -> I-00006 | H7: =アイテム項目!$F7 -> ペン類 | I7: =アイテム項目!$G7 -> 文房具 | J7: =アイテム項目!$H7 -> B | K7: =アイテム項目!$I7 -> ボールペン・シャープ・蛍光ペン等複数本
A8: =IFERROR(INDEX(T項目!$A:$A,MATCH(アイテムビューア!$C8,T項目!$D:$D,0)),"") -> S-001 | B8: =IFERROR(INDEX(S項目!$B:$B,MATCH(アイテムビューア!$A8,S項目!$A:$A,0)),"") -> 玄関棚 | C8: =IFERROR(INDEX(C項目!$A:$A,MATCH(アイテムビューア!$E8,C項目!$D:$D,0)),"") -> T-0102 | D8: =IFERROR(INDEX(T項目!$E:$E,MATCH(アイテムビューア!$C8,T項目!$D:$D,0)),"") -> 上段一段目 | E8: =アイテム項目!$A8 -> C-010201 | F8: =IFERROR(INDEX(C項目!$E:$E,MATCH(アイテムビューア!$E8,C項目!$D:$D,0)),"") -> 小物トレー・カゴ | G8: =アイテム項目!$E8 -> I-00007 | H8: =アイテム項目!$F8 -> 消しゴム | I8: =アイテム項目!$G8 -> 文房具 | J8: =アイテム項目!$H8 -> B | K8: =アイテム項目!$I8 -> MONOゼロノック式
A9: =IFERROR(INDEX(T項目!$A:$A,MATCH(アイテムビューア!$C9,T項目!$D:$D,0)),"") -> S-001 | B9: =IFERROR(INDEX(S項目!$B:$B,MATCH(アイテムビューア!$A9,S項目!$A:$A,0)),"") -> 玄関棚 | C9: =IFERROR(INDEX(C項目!$A:$A,MATCH(アイテムビューア!$E9,C項目!$D:$D,0)),"") -> T-0102 | D9: =IFERROR(INDEX(T項目!$E:$E,MATCH(アイテムビューア!$C9,T項目!$D:$D,0)),"") -> 上段一段目 | E9: =アイテム項目!$A9 -> C-010201 | F9: =IFERROR(INDEX(C項目!$E:$E,MATCH(アイテムビューア!$E9,C項目!$D:$D,0)),"") -> 小物トレー・カゴ | G9: =アイテム項目!$E9 -> I-00008 | H9: =アイテム項目!$F9 -> ハサミ・カッター | I9: =アイテム項目!$G9 -> 工具 | J9: =アイテム項目!$H9 -> B | K9: =アイテム項目!$I9 -> カッターナイフ含む
A10: =IFERROR(INDEX(T項目!$A:$A,MATCH(アイテムビューア!$C10,T項目!$D:$D,0)),"") -> S-001 | B10: =IFERROR(INDEX(S項目!$B:$B,MATCH(アイテムビューア!$A10,S項目!$A:$A,0)),"") -> 玄関棚 | C10: =IFERROR(INDEX(C項目!$A:$A,MATCH(アイテムビューア!$E10,C項目!$D:$D,0)),"") -> T-0102 | D10: =IFERROR(INDEX(T項目!$E:$E,MATCH(アイテムビューア!$C10,T項目!$D:$D,0)),"") -> 上段一段目 | E10: =アイテム項目!$A10 -> C-010201 | F10: =IFERROR(INDEX(C項目!$E:$E,MATCH(アイテムビューア!$E10,C項目!$D:$D,0)),"") -> 小物トレー・カゴ | G10: =アイテム項目!$E10 -> I-00009 | H10: =アイテム項目!$F10 -> つめ切り・爪やすり | I10: =アイテム項目!$G10 -> 日用品 | J10: =アイテム項目!$H10 -> B | K10: =アイテム項目!$I10 -> 台紙付きつめ切り・金属製やすり
A11: =IFERROR(INDEX(T項目!$A:$A,MATCH(アイテムビューア!$C11,T項目!$D:$D,0)),"") -> S-001 | B11: =IFERROR(INDEX(S項目!$B:$B,MATCH(アイテムビューア!$A11,S項目!$A:$A,0)),"") -> 玄関棚 | C11: =IFERROR(INDEX(C項目!$A:$A,MATCH(アイテムビューア!$E11,C項目!$D:$D,0)),"") -> T-0102 | D11: =IFERROR(INDEX(T項目!$E:$E,MATCH(アイテムビューア!$C11,T項目!$D:$D,0)),"") -> 上段一段目 | E11: =アイテム項目!$A11 -> C-010201 | F11: =IFERROR(INDEX(C項目!$E:$E,MATCH(アイテムビューア!$E11,C項目!$D:$D,0)),"") -> 小物トレー・カゴ | G11: =アイテム項目!$E11 -> I-00010 | H11: =アイテム項目!$F11 -> クリップ類 | I11: =アイテム項目!$G11 -> 文房具 | J11: =アイテム項目!$H11 -> B | K11: =アイテム項目!$I11 -> 各種クリップ
A12: =IFERROR(INDEX(T項目!$A:$A,MATCH(アイテムビューア!$C12,T項目!$D:$D,0)),"") -> S-001 | B12: =IFERROR(INDEX(S項目!$B:$B,MATCH(アイテムビューア!$A12,S項目!$A:$A,0)),"") -> 玄関棚 | C12: =IFERROR(INDEX(C項目!$A:$A,MATCH(アイテムビューア!$E12,C項目!$D:$D,0)),"") -> T-0102 | D12: =IFERROR(INDEX(T項目!$E:$E,MATCH(アイテムビューア!$C12,T項目!$D:$D,0)),"") -> 上段一段目 | E12: =アイテム項目!$A12 -> C-010201 | F12: =IFERROR(INDEX(C項目!$E:$E,MATCH(アイテムビューア!$E12,C項目!$D:$D,0)),"") -> 小物トレー・カゴ | G12: =アイテム項目!$E12 -> I-00011 | H12: =アイテム項目!$F12 -> 結束バンド（白） | I12: =アイテム項目!$G12 -> 電材 | J12: =アイテム項目!$H12 -> B | K12: =アイテム項目!$I12 -> 10cm・120本入パッケージ
A13: =IFERROR(INDEX(T項目!$A:$A,MATCH(アイテムビューア!$C13,T項目!$D:$D,0)),"") -> S-001 | B13: =IFERROR(INDEX(S項目!$B:$B,MATCH(アイテムビューア!$A13,S項目!$A:$A,0)),"") -> 玄関棚 | C13: =IFERROR(INDEX(C項目!$A:$A,MATCH(アイテムビューア!$E13,C項目!$D:$D,0)),"") -> T-0102 | D13: =IFERROR(INDEX(T項目!$E:$E,MATCH(アイテムビューア!$C13,T項目!$D:$D,0)),"") -> 上段一段目 | E13: =アイテム項目!$A13 -> C-010201 | F13: =IFERROR(INDEX(C項目!$E:$E,MATCH(アイテムビューア!$E13,C項目!$D:$D,0)),"") -> 小物トレー・カゴ | G13: =アイテム項目!$E13 -> I-00012 | H13: =アイテム項目!$F13 -> 小ネジボックス | I13: =アイテム項目!$G13 -> ネジ | J13: =アイテム項目!$H13 -> B | K13: =アイテム項目!$I13 -> 小ネジ各種入りボックス
... A403: =IFERROR(INDEX(T項目!$A:$A,MATCH(アイテムビューア!$C403,T項目!$D:$D,0)),"") -> S-003 | B403: =IFERROR(INDEX(S項目!$B:$B,MATCH(アイテムビューア!$A403,S項目!$A:$A,0)),"") -> 南ラック | C403: =IFERROR(INDEX(C項目!$A:$A,MATCH(アイテムビューア!$E403,C項目!$D:$D,0)),"") -> T-0304 | D403: =IFERROR(INDEX(T項目!$E:$E,MATCH(アイテムビューア!$C403,T項目!$D:$D,0)),"") -> 左底面 | E403: =アイテム項目!$A403 -> C-030401 | F403: =IFERROR(INDEX(C項目!$E:$E,MATCH(アイテムビューア!$E403,C項目!$D:$D,0)),"") -> 工具キャリーバッグ（赤黒） | G403: =アイテム項目!$E403 -> I-00387 | H403: =アイテム項目!$F403 -> 電動ドライバ（ミニ） | I403: =アイテム項目!$G403 -> ドライバ | J403: =アイテム項目!$H403 -> B | K403: =アイテム項目!$I403 -> 小さい電動ドライバ
A404: =IFERROR(INDEX(T項目!$A:$A,MATCH(アイテムビューア!$C404,T項目!$D:$D,0)),"") | B404: =IFERROR(INDEX(S項目!$B:$B,MATCH(アイテムビューア!$A404,S項目!$A:$A,0)),"") | C404: =IFERROR(INDEX(C項目!$A:$A,MATCH(アイテムビューア!$E404,C項目!$D:$D,0)),"") | D404: =IFERROR(INDEX(T項目!$E:$E,MATCH(アイテムビューア!$C404,T項目!$D:$D,0)),"") | E404: =アイテム項目!$A404 -> 0 | F404: =IFERROR(INDEX(C項目!$E:$E,MATCH(アイテムビューア!$E404,C項目!$D:$D,0)),"") | G404: =アイテム項目!$E404 -> 0 | H404: =アイテム項目!#REF! -> #REF! | I404: =アイテム項目!$G404 -> 0 | J404: =アイテム項目!$H404 -> 0 | K404: =アイテム項目!$I404 -> 0
A405: =IFERROR(INDEX(T項目!$A:$A,MATCH(アイテムビューア!$C405,T項目!$D:$D,0)),"") | B405: =IFERROR(INDEX(S項目!$B:$B,MATCH(アイテムビューア!$A405,S項目!$A:$A,0)),"") | C405: =IFERROR(INDEX(C項目!$A:$A,MATCH(アイテムビューア!$E405,C項目!$D:$D,0)),"") | D405: =IFERROR(INDEX(T項目!$E:$E,MATCH(アイテムビューア!$C405,T項目!$D:$D,0)),"") | E405: =アイテム項目!$A405 -> 0 | F405: =IFERROR(INDEX(C項目!$E:$E,MATCH(アイテムビューア!$E405,C項目!$D:$D,0)),"") | G405: =アイテム項目!$E405 -> 0 | H405: =アイテム項目!$F405 -> 0 | I405: =アイテム項目!$G405 -> 0 | J405: =アイテム項目!$H405 -> 0 | K405: =アイテム項目!$I405 -> 0
A406: =IFERROR(INDEX(T項目!$A:$A,MATCH(アイテムビューア!$C406,T項目!$D:$D,0)),"") | B406: =IFERROR(INDEX(S項目!$B:$B,MATCH(アイテムビューア!$A406,S項目!$A:$A,0)),"") | C406: =IFERROR(INDEX(C項目!$A:$A,MATCH(アイテムビューア!$E406,C項目!$D:$D,0)),"") | D406: =IFERROR(INDEX(T項目!$E:$E,MATCH(アイテムビューア!$C406,T項目!$D:$D,0)),"") | E406: =アイテム項目!$A406 -> 0 | F406: =IFERROR(INDEX(C項目!$E:$E,MATCH(アイテムビューア!$E406,C項目!$D:$D,0)),"") | G406: =アイテム項目!$E406 -> 0 | H406: =アイテム項目!$F406 -> 0 | I406: =アイテム項目!$G406 -> 0 | J406: =アイテム項目!$H406 -> 0 | K406: =アイテム項目!$I406 -> 0
A407: =IFERROR(INDEX(T項目!$A:$A,MATCH(アイテムビューア!$C407,T項目!$D:$D,0)),"") | B407: =IFERROR(INDEX(S項目!$B:$B,MATCH(アイテムビューア!$A407,S項目!$A:$A,0)),"") | C407: =IFERROR(INDEX(C項目!$A:$A,MATCH(アイテムビューア!$E407,C項目!$D:$D,0)),"") | D407: =IFERROR(INDEX(T項目!$E:$E,MATCH(アイテムビューア!$C407,T項目!$D:$D,0)),"") | E407: =アイテム項目!$A407 -> 0 | F407: =IFERROR(INDEX(C項目!$E:$E,MATCH(アイテムビューア!$E407,C項目!$D:$D,0)),"") | G407: =アイテム項目!$E407 -> 0 | H407: =アイテム項目!$F407 -> 0 | I407: =アイテム項目!$G407 -> 0 | J407: =アイテム項目!$H407 -> 0 | K407: =アイテム項目!$I407 -> 0
A408: =IFERROR(INDEX(T項目!$A:$A,MATCH(アイテムビューア!$C408,T項目!$D:$D,0)),"") | B408: =IFERROR(INDEX(S項目!$B:$B,MATCH(アイテムビューア!$A408,S項目!$A:$A,0)),"") | C408: =IFERROR(INDEX(C項目!$A:$A,MATCH(アイテムビューア!$E408,C項目!$D:$D,0)),"") | D408: =IFERROR(INDEX(T項目!$E:$E,MATCH(アイテムビューア!$C408,T項目!$D:$D,0)),"") | E408: =アイテム項目!$A408 -> 0 | F408: =IFERROR(INDEX(C項目!$E:$E,MATCH(アイテムビューア!$E408,C項目!$D:$D,0)),"") | G408: =アイテム項目!$E408 -> 0 | H408: =アイテム項目!$F408 -> 0 | I408: =アイテム項目!$G408 -> 0 | J408: =アイテム項目!$H408 -> 0 | K408: =アイテム項目!$I408 -> 0
A409: =IFERROR(INDEX(T項目!$A:$A,MATCH(アイテムビューア!$C409,T項目!$D:$D,0)),"") | B409: =IFERROR(INDEX(S項目!$B:$B,MATCH(アイテムビューア!$A409,S項目!$A:$A,0)),"") | C409: =IFERROR(INDEX(C項目!$A:$A,MATCH(アイテムビューア!$E409,C項目!$D:$D,0)),"") | D409: =IFERROR(INDEX(T項目!$E:$E,MATCH(アイテムビューア!$C409,T項目!$D:$D,0)),"") | E409: =アイテム項目!$A409 -> 0 | F409: =IFERROR(INDEX(C項目!$E:$E,MATCH(アイテムビューア!$E409,C項目!$D:$D,0)),"") | G409: =アイテム項目!$E409 -> 0 | H409: =アイテム項目!$F409 -> 0 | I409: =アイテム項目!$G409 -> 0 | J409: =アイテム項目!$H409 -> 0 | K409: =アイテム項目!$I409 -> 0
A410: =IFERROR(INDEX(T項目!$A:$A,MATCH(アイテムビューア!$C410,T項目!$D:$D,0)),"") | B410: =IFERROR(INDEX(S項目!$B:$B,MATCH(アイテムビューア!$A410,S項目!$A:$A,0)),"") | C410: =IFERROR(INDEX(C項目!$A:$A,MATCH(アイテムビューア!$E410,C項目!$D:$D,0)),"") | D410: =IFERROR(INDEX(T項目!$E:$E,MATCH(アイテムビューア!$C410,T項目!$D:$D,0)),"") | E410: =アイテム項目!$A410 -> 0 | F410: =IFERROR(INDEX(C項目!$E:$E,MATCH(アイテムビューア!$E410,C項目!$D:$D,0)),"") | G410: =アイテム項目!$E410 -> 0 | H410: =アイテム項目!$F410 -> 0 | I410: =アイテム項目!$G410 -> 0 | J410: =アイテム項目!$H410 -> 0 | K410: =アイテム項目!$I410 -> 0
A411: =IFERROR(INDEX(T項目!$A:$A,MATCH(アイテムビューア!$C411,T項目!$D:$D,0)),"") | B411: =IFERROR(INDEX(S項目!$B:$B,MATCH(アイテムビューア!$A411,S項目!$A:$A,0)),"") | C411: =IFERROR(INDEX(C項目!$A:$A,MATCH(アイテムビューア!$E411,C項目!$D:$D,0)),"") | D411: =IFERROR(INDEX(T項目!$E:$E,MATCH(アイテムビューア!$C411,T項目!$D:$D,0)),"") | E411: =アイテム項目!$A411 -> 0 | F411: =IFERROR(INDEX(C項目!$E:$E,MATCH(アイテムビューア!$E411,C項目!$D:$D,0)),"") | G411: =アイテム項目!$E411 -> 0 | H411: =アイテム項目!$F411 -> 0 | I411: =アイテム項目!$G411 -> 0 | J411: =アイテム項目!$H411 -> 0 | K411: =アイテム項目!$I411 -> 0
A412: =IFERROR(INDEX(T項目!$A:$A,MATCH(アイテムビューア!$C412,T項目!$D:$D,0)),"") | B412: =IFERROR(INDEX(S項目!$B:$B,MATCH(アイテムビューア!$A412,S項目!$A:$A,0)),"") | C412: =IFERROR(INDEX(C項目!$A:$A,MATCH(アイテムビューア!$E412,C項目!$D:$D,0)),"") | D412: =IFERROR(INDEX(T項目!$E:$E,MATCH(アイテムビューア!$C412,T項目!$D:$D,0)),"") | E412: =アイテム項目!$A412 -> 0 | F412: =IFERROR(INDEX(C項目!$E:$E,MATCH(アイテムビューア!$E412,C項目!$D:$D,0)),"") | G412: =アイテム項目!$E412 -> 0 | H412: =アイテム項目!$F412 -> 0 | I412: =アイテム項目!$G412 -> 0 | J412: =アイテム項目!$H412 -> 0 | K412: =アイテム項目!$I412 -> 0
A413: =IFERROR(INDEX(T項目!$A:$A,MATCH(アイテムビューア!$C413,T項目!$D:$D,0)),"") | B413: =IFERROR(INDEX(S項目!$B:$B,MATCH(アイテムビューア!$A413,S項目!$A:$A,0)),"") | C413: =IFERROR(INDEX(C項目!$A:$A,MATCH(アイテムビューア!$E413,C項目!$D:$D,0)),"") | D413: =IFERROR(INDEX(T項目!$E:$E,MATCH(アイテムビューア!$C413,T項目!$D:$D,0)),"") | E413: =アイテム項目!$A413 -> 0 | F413: =IFERROR(INDEX(C項目!$E:$E,MATCH(アイテムビューア!$E413,C項目!$D:$D,0)),"") | G413: =アイテム項目!$E413 -> 0 | H413: =アイテム項目!$F413 -> 0 | I413: =アイテム項目!$G413 -> 0 | J413: =アイテム項目!$H413 -> 0 | K413: =アイテム項目!$I413 -> 0
A414: =IFERROR(INDEX(T項目!$A:$A,MATCH(アイテムビューア!$C414,T項目!$D:$D,0)),"") | B414: =IFERROR(INDEX(S項目!$B:$B,MATCH(アイテムビューア!$A414,S項目!$A:$A,0)),"") | C414: =IFERROR(INDEX(C項目!$A:$A,MATCH(アイテムビューア!$E414,C項目!$D:$D,0)),"") | D414: =IFERROR(INDEX(T項目!$E:$E,MATCH(アイテムビューア!$C414,T項目!$D:$D,0)),"") | E414: =アイテム項目!$A414 -> 0 | F414: =IFERROR(INDEX(C項目!$E:$E,MATCH(アイテムビューア!$E414,C項目!$D:$D,0)),"") | G414: =アイテム項目!$E414 -> 0 | H414: =アイテム項目!$F414 -> 0 | I414: =アイテム項目!$G414 -> 0 | J414: =アイテム項目!$H414 -> 0 | K414: =アイテム項目!$I414 -> 0
A415: =IFERROR(INDEX(T項目!$A:$A,MATCH(アイテムビューア!$C415,T項目!$D:$D,0)),"") | B415: =IFERROR(INDEX(S項目!$B:$B,MATCH(アイテムビューア!$A415,S項目!$A:$A,0)),"") | C415: =IFERROR(INDEX(C項目!$A:$A,MATCH(アイテムビューア!$E415,C項目!$D:$D,0)),"") | D415: =IFERROR(INDEX(T項目!$E:$E,MATCH(アイテムビューア!$C415,T項目!$D:$D,0)),"") | E415: =アイテム項目!$A415 -> 0 | F415: =IFERROR(INDEX(C項目!$E:$E,MATCH(アイテムビューア!$E415,C項目!$D:$D,0)),"") | G415: =アイテム項目!$E415 -> 0 | H415: =アイテム項目!$F415 -> 0 | I415: =アイテム項目!$G415 -> 0 | J415: =アイテム項目!$H415 -> 0 | K415: =アイテム項目!$I415 -> 0
A416: =IFERROR(INDEX(T項目!$A:$A,MATCH(アイテムビューア!$C416,T項目!$D:$D,0)),"") | B416: =IFERROR(INDEX(S項目!$B:$B,MATCH(アイテムビューア!$A416,S項目!$A:$A,0)),"") | C416: =IFERROR(INDEX(C項目!$A:$A,MATCH(アイテムビューア!$E416,C項目!$D:$D,0)),"") | D416: =IFERROR(INDEX(T項目!$E:$E,MATCH(アイテムビューア!$C416,T項目!$D:$D,0)),"") | E416: =アイテム項目!$A416 -> 0 | F416: =IFERROR(INDEX(C項目!$E:$E,MATCH(アイテムビューア!$E416,C項目!$D:$D,0)),"") | G416: =アイテム項目!$E416 -> 0 | H416: =アイテム項目!$F416 -> 0 | I416: =アイテム項目!$G416 -> 0 | J416: =アイテム項目!$H416 -> 0 | K416: =アイテム項目!$I416 -> 0
... A492: =IFERROR(INDEX(T項目!$A:$A,MATCH(アイテムビューア!$C492,T項目!$D:$D,0)),"") | B492: =IFERROR(INDEX(S項目!$B:$B,MATCH(アイテムビューア!$A492,S項目!$A:$A,0)),"") | C492: =IFERROR(INDEX(C項目!$A:$A,MATCH(アイテムビューア!$E492,C項目!$D:$D,0)),"") | D492: =IFERROR(INDEX(T項目!$E:$E,MATCH(アイテムビューア!$C492,T項目!$D:$D,0)),"") | E492: =アイテム項目!$A492 -> 0 | F492: =IFERROR(INDEX(C項目!$E:$E,MATCH(アイテムビューア!$E492,C項目!$D:$D,0)),"") | G492: =アイテム項目!$E492 -> 0 | H492: =アイテム項目!$F492 -> 0 | I492: =アイテム項目!$G492 -> 0 | J492: =アイテム項目!$H492 -> 0 | K492: =アイテム項目!$I492 -> 0

Sheet 全体配置
A9: 送り先：ぷれこ
A10: 発信者：ChatGPT
A12: 内容：
A14: 【エリア特性シート Ver.1.1（反映版）】
A16: ■ 北押入れ 上段
A18: ・取り出しやすさ：E
A19: ・脚立必要：必要
A20: ・重い物向き：だめだめ
A21: ・軽い物向き：出来るだけ
A22: ・長期保管向き：基本保管のみ
A23: ・頻繁利用向き：不可
A24: ・利用率：30％
... A79: ・主な用途：
A80: ・奥行き：幅 × 奥行 × 高さ(cm) | C80: 175 | D80: 80 | E80: 55
A81: ・備考： | B81: 空箱 ぱっとみ不要な物を箱にいれて突っ込んでます
A85: ■ 南押入れ 中段
A87: ・取り出しやすさ： | B87: A
A88: ・脚立必要：
A89: ・重い物向き：
A90: ・軽い物向き： | B90: 良
A91: ・長期保管向き： | B91: 不良
A92: ・頻繁利用向き： | B92: 良
A93: ・利用率： | B93: 0.8
A94: ・主な用途： | B94: 工具他
A95: ・奥行き：幅 × 奥行 × 高さ(cm) | C95: 175 | D95: 80 | E95: 80
A96: ・備考： | B96: 右側から70％を利用して4段タンスが入っています。中身はかなり煩雑です。
A100: ■ 南押入れ 下段
A102: ・取り出しやすさ： | B102: B
A103: ・脚立必要： | B103: 不要
A104: ・重い物向き： | B104: 良
A105: ・軽い物向き：
A106: ・長期保管向き： | B106: 中期向き
A107: ・頻繁利用向き：
A108: ・利用率： | B108: 0.8
A109: ・主な用途： | B109: 右65％を利用して机を置いています。机の上にA3プリンタ、ラミネーターを設置中
A110: ・奥行き：幅 × 奥行 × 高さ(cm) | C110: 175 | D110: 80 | E110: 80
A111: ・備考：
A115: ■ 電工作業台
A117: ・取り出しやすさ：S
A118: ・脚立必要：不要
...

Sheet 列名一覧
B1: parent_id | C1: parent_type | D1: parent_name | E1: type | F1: Items-ID | G1: Items名称 | H1: usage | I1: access | J1: 備考
A2: カタカナ | B2: ペアレントID | C2: ペアレントタイプ | D2: ペアレントネーム | E2: タイプ | F2: アイテムID | G2: アイテムメイショウ | H2: ユーセージ | I2: アクセス | J2: ビコウ
A3: 日本語 | B3: 親ID | C3: 親種類 | D3: 親名称 | E3: 分類 | F3: アイテムID | G3: アイテム名称 | H3: 用途 | I3: 場所 （または取り出しやすさ） | J3: 備考
A4: 説明 | B4: 親レコードID | C4: 親の種類 | D4: 親レコード名 | E4: 何であるか | F4: 管理ID | G4: 登録名称 | H4: 何に使うか | I4: 保管場所など | J4: 補足情報
